Workbook

Sheet README
A1: Workforce Intelligence - Additional Datasets (Workload Rebalancing + Skill Gap & Training)
A2: Built on top of Workforce_Intelligence_Datasets.xlsx - same employee_id / task_id / skill_id / course_id keys, reference date 15 Oct 2026, snapshot week 19 Oct 2026. Synthetic data.
A4: Sheet | B4: Widget | C4: Description
A5: workload_config | B5: Workload | C5: Thresholds (blue = editable inputs). Drives every bucket/percentage via formulas.
A6: workload_history | B6: Workload | C6: 60 employees x 9 weeks (24 Aug - 19 Oct): allocated vs capacity, bucket, movable/locked hours, overtime. Derived from task start dates.
A7: rebalance_recommendations | B7: Workload | C7: Proposed task moves (what Auto-Rebalance Tasks would apply) with skill match score and before/after load.
A8: rebalance_employee_impact | B8: Workload | C8: Per-employee before/after utilization (formulas) - feeds Over-utilized / Under-utilized staff lists.
A9: rebalance_log | B9: Workload | C9: 16 past rebalances with outcome - history / training data.
A10: workload_dashboard_summary | B10: Workload | C10: Overloaded / Underutilized / Optimal counts and % (formulas), before and after rebalance.
A11: employee_skill_gaps | B11: Skill gap | C11: One row per employee x skill below the required level (current assignments + upcoming-project staffing).
A12: training_recommendations | B12: Skill gap | C12: Course path or mentor per gap, priority score, capacity check, planned dates.
A13: course_enrollments | B13: Skill gap | C13: In-progress and completed enrollments (in-progress rows mark gaps as "In training").
A14: training_budget | B14: Skill gap | C14: Department budget vs spent / committed / pending (formulas). Annual budget is an assumed input.
A15: skill_supply_vs_demand | B15: Skill gap | C15: Bench strength per skill required by active/upcoming projects.
A16: skill_gap_dashboard_summary | B16: Skill gap | C16: Exact table layout of the screenshot: Skill | Gap | Recommended | Action (formulas).
A18: Assumptions: gap = required level - effective level (related skills count with similarity credit, e.g. AWS counts toward Cloud Computing). Upcoming-project candidates are people below 87.5% load who are 1-2 levels short or interested at 4+. Names in your screenshot (Ariel Sharma, Ravi Kumar) are not in the employee master, so real employees are used.

Sheet workload_config
A1: parameter | B1: value | C1: notes
A2: overloaded_threshold_pct | B2: 87.5 | C2: Utilization >= this = Overloaded bucket (35 of 40 hrs). Tuned so the 60-person snapshot gives 15% / 12% / 73%. Change to re-bucket everything.
A3: underutilized_threshold_pct | B3: 50 | C3: Utilization < this = Underutilized
A4: target_util_after_rebalance_pct | B4: 80 | C4: Rebalancer moves tasks out until the person is at or below this
A5: receiver_max_util_pct | B5: 80 | C5: Preferred ceiling for a person receiving tasks (relaxed to 87 in a second pass)
A6: critical_threshold_pct | B6: 100 | C6: Utilization above this = over capacity (critical)
A7: latest_snapshot_week | B7: 2026-10-19 | C7: Week used by dashboard summary
A8: team_size | B8: 60 | C8: Employees in snapshot

Sheet workload_history
A1: week_start | B1: week_type | C1: employee_id | D1: employee_name | E1: department | F1: allocated_hrs | G1: capacity_hrs | H1: utilization_pct | I1: load_bucket | J1: task_count | K1: movable_hrs | L1: locked_hrs | M1: overtime_hrs_logged
A2: 2026-08-24 | B2: actual | C2: E001 | D2: Ravi Shankar | E2: Backend | F2: 20 | G2: 40 | H2: =ROUND(F2/G2*100,0) -> 50 | I2: =IF(H2>=workload_config!$B$2,"Overloaded",IF(H2<workload_config!$B$3,"Underutilized","Optimal")) -> Optimal | J2: 2 | K2: 0 | L2: 20 | M2: 0
A3: 2026-08-24 | B3: actual | C3: E002 | D3: Anita Rao | E3: Backend | F3: 7 | G3: 40 | H3: =ROUND(F3/G3*100,0) -> 18 | I3: =IF(H3>=workload_config!$B$2,"Overloaded",IF(H3<workload_config!$B$3,"Underutilized","Optimal")) -> Underutilized | J3: 1 | K3: 7 | L3: 0 | M3: 0
A4: 2026-08-24 | B4: actual | C4: E003 | D4: Karthik Subramanian | E4: Backend | F4: 12 | G4: 40 | H4: =ROUND(F4/G4*100,0) -> 30 | I4: =IF(H4>=workload_config!$B$2,"Overloaded",IF(H4<workload_config!$B$3,"Underutilized","Optimal")) -> Underutilized | J4: 1 | K4: 12 | L4: 0 | M4: 0
A5: 2026-08-24 | B5: actual | C5: E004 | D5: Vikram Joshi | E5: Backend | F5: 8 | G5: 40 | H5: =ROUND(F5/G5*100,0) -> 20 | I5: =IF(H5>=workload_config!$B$2,"Overloaded",IF(H5<workload_config!$B$3,"Underutilized","Optimal")) -> Underutilized | J5: 1 | K5: 8 | L5: 0 | M5: 0
A6: 2026-08-24 | B6: actual | C6: E005 | D6: Sandeep Kulkarni | E6: Backend | F6: 11 | G6: 40 | H6: =ROUND(F6/G6*100,0) -> 28 | I6: =IF(H6>=workload_config!$B$2,"Overloaded",IF(H6<workload_config!$B$3,"Underutilized","Optimal")) -> Underutilized | J6: 1 | K6: 11 | L6: 0 | M6: 0
A7: 2026-08-24 | B7: actual | C7: E006 | D7: Pooja Bhat | E7: Backend | F7: 20 | G7: 40 | H7: =ROUND(F7/G7*100,0) -> 50 | I7: =IF(H7>=workload_config!$B$2,"Overloaded",IF(H7<workload_config!$B$3,"Underutilized","Optimal")) -> Optimal | J7: 2 | K7: 20 | L7: 0 | M7: 0
A8: 2026-08-24 | B8: actual | C8: E007 | D8: Harish Gowda | E8: Backend | F8: 20 | G8: 40 | H8: =ROUND(F8/G8*100,0) -> 50 | I8: =IF(H8>=workload_config!$B$2,"Overloaded",IF(H8<workload_config!$B$3,"Underutilized","Optimal")) -> Optimal | J8: 2 | K8: 20 | L8: 0 | M8: 0
A9: 2026-08-24 | B9: actual | C9: E008 | D9: Lakshmi Narayan | E9: Backend | F9: 11 | G9: 40 | H9: =ROUND(F9/G9*100,0) -> 28 | I9: =IF(H9>=workload_config!$B$2,"Overloaded",IF(H9<workload_config!$B$3,"Underutilized","Optimal")) -> Underutilized | J9: 1 | K9: 0 | L9: 11 | M9: 0
A10: 2026-08-24 | B10: actual | C10: E009 | D10: Imran Sheikh | E10: Backend | F10: 10 | G10: 40 | H10: =ROUND(F10/G10*100,0) -> 25 | I10: =IF(H10>=workload_config!$B$2,"Overloaded",IF(H10<workload_config!$B$3,"Underutilized","Optimal")) -> Underutilized | J10: 1 | K10: 0 | L10: 10 | M10: 0
A11: 2026-08-24 | B11: actual | C11: E010 | D11: Deepak Chauhan | E11: Backend | F11: 11 | G11: 40 | H11: =ROUND(F11/G11*100,0) -> 28 | I11: =IF(H11>=workload_config!$B$2,"Overloaded",IF(H11<workload_config!$B$3,"Underutilized","Optimal")) -> Underutilized | J11: 1 | K11: 11 | L11: 0 | M11: 0
A12: 2026-08-24 | B12: actual | C12: E011 | D12: Shreya Pillai | E12: Backend | F12: 0 | G12: 40 | H12: =ROUND(F12/G12*100,0) -> 0 | I12: =IF(H12>=workload_config!$B$2,"Overloaded",IF(H12<workload_config!$B$3,"Underutilized","Optimal")) -> Underutilized | J12: 0 | K12: 0 | L12: 0 | M12: 0
A13: 2026-08-24 | B13: actual | C13: E012 | D13: Manoj Kumar | E13: Backend | F13: 0 | G13: 40 | H13: =ROUND(F13/G13*100,0) -> 0 | I13: =IF(H13>=workload_config!$B$2,"Overloaded",IF(H13<workload_config!$B$3,"Underutilized","Optimal")) -> Underutilized | J13: 0 | K13: 0 | L13: 0 | M13: 0
... A541: 2026-10-19 | B541: planned | C541: E060 | D541: Teja Reddy | E541: Delivery & Quality | F541: 25 | G541: 40 | H541: =ROUND(F541/G541*100,0) -> 63 | I541: =IF(H541>=workload_config!$B$2,"Overloaded",IF(H541<workload_config!$B$3,"Underutilized","Optimal")) -> Optimal | J541: 2 | K541: 12 | L541: 13 | M541: 0

Sheet rebalance_recommendations
A1: rec_id | B1: snapshot_week | C1: task_id | D1: task_name | E1: project_id | F1: task_priority | G1: required_skill_id | H1: required_skill | I1: min_level | J1: hours_moved | K1: from_employee_id | L1: from_name | M1: to_employee_id | N1: to_name | O1: receiver_skill_level | P1: same_department | Q1: from_util_before_pct | R1: from_util_after_pct | S1: to_util_before_pct | T1: to_util_after_pct | U1: match_score | V1: reason | W1: status
A2: RB001 | B2: 2026-10-19 | C2: T082 | D2: Sales dashboards | E2: P06 | F2: Medium | G2: S31 | H2: Tableau | I2: 2 | J2: 10 | K2: E028 | L2: Divya Menon | M2: E036 | N2: Zoya Ansari | O2: 3 | P2: Y | Q2: 125 | R2: 100 | S2: 35 | T2: 60 | U2: 79 | V2: Divya Menon at 125% load; Zoya Ansari has Tableau level 3 (needs 2) and 35% load | W2: suggested
A3: RB002 | B3: 2026-10-19 | C3: T084 | D3: Ingestion framework | E3: P06 | F3: Medium | G3: S32 | H3: Data Engineering | I3: 3 | J3: 7 | K3: E028 | L3: Divya Menon | M3: E031 | N3: Rajesh Pandey | O3: 3 | P3: Y | Q3: 100 | R3: 82 | S3: 60 | T3: 78 | U3: 61 | V3: Divya Menon at 100% load; Rajesh Pandey has Data Engineering level 3 (needs 3) and 60% load | W3: suggested
A4: RB003 | B4: 2026-10-19 | C4: T004 | D4: Pipeline KPI refactor | E4: P07 | F4: Medium | G4: S28 | H4: Data Analytics | I4: 3 | J4: 11 | K4: E001 | L4: Ravi Shankar | M4: E002 | N4: Anita Rao | O4: 3 | P4: Y | Q4: 118 | R4: 90 | S4: 40 | T4: 68 | U4: 68 | V4: Ravi Shankar at 118% load; Anita Rao has Data Analytics level 3 (needs 3) and 40% load | W4: suggested
A5: RB004 | B5: 2026-10-19 | C5: T001 | D5: Report automation | E5: P05 | F5: Medium | G5: S01 | H5: Python | I5: 3 | J5: 8 | K5: E001 | L5: Ravi Shankar | M5: E026 | N5: Priya Nair | O5: 5 | P5: N | Q5: 90 | R5: 70 | S5: 50 | T5: 70 | U5: 62 | V5: Ravi Shankar at 90% load; Priya Nair has Python level 5 (needs 3) and 50% load | W5: suggested
A6: RB005 | B6: 2026-10-19 | C6: T011 | D6: Schema migration | E6: P04 | F6: Medium | G6: S15 | H6: SQL | I6: 4 | J6: 14 | K6: E003 | L6: Karthik Subramanian | M6: E055 | N6: Harsha Vardhan | O6: 4 | P6: N | Q6: 112 | R6: 78 | S6: 40 | T6: 75 | U6: 48 | V6: Karthik Subramanian at 112% load; Harsha Vardhan has SQL level 4 (needs 4) and 40% load | W6: suggested
A7: RB006 | B7: 2026-10-19 | C7: T128 | D7: Notification service | E7: P01 | F7: Low | G7: S10 | H7: Node.js | I7: 2 | J7: 9 | K7: E044 | L7: Siddharth Rao | M7: E040 | N7: Rohan Das | O7: 4 | P7: Y | Q7: 100 | R7: 78 | S7: 40 | T7: 62 | U7: 86 | V7: Siddharth Rao at 100% load; Rohan Das has Node.js level 4 (needs 2) and 40% load | W7: suggested
A8: RB007 | B8: 2026-10-19 | C8: T013 | D8: Integration scripts | E8: P05 | F8: Low | G8: S01 | H8: Python | I8: 3 | J8: 14 | K8: E004 | L8: Vikram Joshi | M8: E017 | N8: Nikhil Agarwal | O8: 3 | P8: N | Q8: 95 | R8: 60 | S8: 30 | T8: 65 | U8: 52 | V8: Vikram Joshi at 95% load; Nikhil Agarwal has Python level 3 (needs 3) and 30% load | W8: suggested
A9: RB008 | B9: 2026-10-19 | C9: T064 | D9: Blob storage migration | E9: P05 | F9: Low | G9: S21 | H9: Azure | I9: 2 | J9: 12 | K9: E022 | L9: Rekha Murthy | M9: E016 | N9: Suresh Babu | O9: 3 | P9: Y | Q9: 95 | R9: 65 | S9: 50 | T9: 80 | U9: 74 | V9: Rekha Murthy at 95% load; Suresh Babu has Azure level 3 (needs 2) and 50% load | W9: suggested
A10: RB009 | B10: 2026-10-19 | C10: T056 | D10: Server patching | E10: P07 | F10: Medium | G10: S27 | H10: Linux | I10: 3 | J10: 9 | K10: E019 | L10: Gautham Prabhu | M10: E015 | N10: Arjun Mehta | O10: 4 | P10: Y | Q10: 90 | R10: 68 | S10: 38 | T10: 60 | U10: 78 | V10: Gautham Prabhu at 90% load; Arjun Mehta has Linux level 4 (needs 3) and 38% load | W10: suggested
A11: RB010 | B11: 2026-10-19 | C11: T091 | D11: Ad-hoc analysis requests | E11: P03 | F11: Medium | G11: S28 | H11: Data Analytics | I11: 3 | J11: 10 | K11: E030 | L11: Sneha Kamath | M11: E036 | N11: Zoya Ansari | O11: 4 | P11: Y | Q11: 98 | R11: 72 | S11: 60 | T11: 85 | U11: 70 | V11: Relaxed headroom: Sneha Kamath at 98% load; Zoya Ansari has Data Analytics level 4 (needs 3) and 60% load | W11: suggested

Sheet rebalance_employee_impact
A1: employee_id | B1: name | C1: role | D1: department | E1: allocated_hrs_before | F1: capacity_hrs | G1: util_before_pct | H1: hrs_moved_out | I1: hrs_moved_in | J1: allocated_hrs_after | K1: util_after_pct | L1: bucket_before | M1: bucket_after | N1: free_hrs_to_target
A2: E028 | B2: Divya Menon | C2: Senior Data Scientist | D2: Data & AI | E2: 50 | F2: 40 | G2: =ROUND(E2/F2*100,0) -> 125 | H2: =SUMIFS(rebalance_recommendations!$J:$J,rebalance_recommendations!$K:$K,A2) -> 17 | I2: =SUMIFS(rebalance_recommendations!$J:$J,rebalance_recommendations!$M:$M,A2) -> 0 | J2: =E2-H2+I2 -> 33 | K2: =ROUND(J2/F2*100,0) -> 83 | L2: =IF(G2>=workload_config!$B$2,"Overloaded",IF(G2<workload_config!$B$3,"Underutilized","Optimal")) -> Overloaded | M2: =IF(K2>=workload_config!$B$2,"Overloaded",IF(K2<workload_config!$B$3,"Underutilized","Optimal")) -> Optimal | N2: =MAX(0,ROUND(F2*workload_config!$B$4/100-J2,0)) -> 0
A3: E001 | B3: Ravi Shankar | C3: Lead Backend Engineer | D3: Backend | E3: 47 | F3: 40 | G3: =ROUND(E3/F3*100,0) -> 118 | H3: =SUMIFS(rebalance_recommendations!$J:$J,rebalance_recommendations!$K:$K,A3) -> 19 | I3: =SUMIFS(rebalance_recommendations!$J:$J,rebalance_recommendations!$M:$M,A3) -> 0 | J3: =E3-H3+I3 -> 28 | K3: =ROUND(J3/F3*100,0) -> 70 | L3: =IF(G3>=workload_config!$B$2,"Overloaded",IF(G3<workload_config!$B$3,"Underutilized","Optimal")) -> Overloaded | M3: =IF(K3>=workload_config!$B$2,"Overloaded",IF(K3<workload_config!$B$3,"Underutilized","Optimal")) -> Optimal | N3: =MAX(0,ROUND(F3*workload_config!$B$4/100-J3,0)) -> 4
A4: E003 | B4: Karthik Subramanian | C4: Lead Backend Engineer | D4: Backend | E4: 45 | F4: 40 | G4: =ROUND(E4/F4*100,0) -> 113 | H4: =SUMIFS(rebalance_recommendations!$J:$J,rebalance_recommendations!$K:$K,A4) -> 14 | I4: =SUMIFS(rebalance_recommendations!$J:$J,rebalance_recommendations!$M:$M,A4) -> 0 | J4: =E4-H4+I4 -> 31 | K4: =ROUND(J4/F4*100,0) -> 78 | L4: =IF(G4>=workload_config!$B$2,"Overloaded",IF(G4<workload_config!$B$3,"Underutilized","Optimal")) -> Overloaded | M4: =IF(K4>=workload_config!$B$2,"Overloaded",IF(K4<workload_config!$B$3,"Underutilized","Optimal")) -> Optimal | N4: =MAX(0,ROUND(F4*workload_config!$B$4/100-J4,0)) -> 1
A5: E044 | B5: Siddharth Rao | C5: Lead Frontend Developer | D5: Frontend & Mobile | E5: 40 | F5: 40 | G5: =ROUND(E5/F5*100,0) -> 100 | H5: =SUMIFS(rebalance_recommendations!$J:$J,rebalance_recommendations!$K:$K,A5) -> 9 | I5: =SUMIFS(rebalance_recommendations!$J:$J,rebalance_recommendations!$M:$M,A5) -> 0 | J5: =E5-H5+I5 -> 31 | K5: =ROUND(J5/F5*100,0) -> 78 | L5: =IF(G5>=workload_config!$B$2,"Overloaded",IF(G5<workload_config!$B$3,"Underutilized","Optimal")) -> Overloaded | M5: =IF(K5>=workload_config!$B$2,"Overloaded",IF(K5<workload_config!$B$3,"Underutilized","Optimal")) -> Optimal | N5: =MAX(0,ROUND(F5*workload_config!$B$4/100-J5,0)) -> 1
A6: E030 | B6: Sneha Kamath | C6: Senior Data Engineer | D6: Data & AI | E6: 39 | F6: 40 | G6: =ROUND(E6/F6*100,0) -> 98 | H6: =SUMIFS(rebalance_recommendations!$J:$J,rebalance_recommendations!$K:$K,A6) -> 10 | I6: =SUMIFS(rebalance_recommendations!$J:$J,rebalance_recommendations!$M:$M,A6) -> 0 | J6: =E6-H6+I6 -> 29 | K6: =ROUND(J6/F6*100,0) -> 73 | L6: =IF(G6>=workload_config!$B$2,"Overloaded",IF(G6<workload_config!$B$3,"Underutilized","Optimal")) -> Overloaded | M6: =IF(K6>=workload_config!$B$2,"Overloaded",IF(K6<workload_config!$B$3,"Underutilized","Optimal")) -> Optimal | N6: =MAX(0,ROUND(F6*workload_config!$B$4/100-J6,0)) -> 3
A7: E004 | B7: Vikram Joshi | C7: Senior Backend Engineer | D7: Backend | E7: 38 | F7: 40 | G7: =ROUND(E7/F7*100,0) -> 95 | H7: =SUMIFS(rebalance_recommendations!$J:$J,rebalance_recommendations!$K:$K,A7) -> 14 | I7: =SUMIFS(rebalance_recommendations!$J:$J,rebalance_recommendations!$M:$M,A7) -> 0 | J7: =E7-H7+I7 -> 24 | K7: =ROUND(J7/F7*100,0) -> 60 | L7: =IF(G7>=workload_config!$B$2,"Overloaded",IF(G7<workload_config!$B$3,"Underutilized","Optimal")) -> Overloaded | M7: =IF(K7>=workload_config!$B$2,"Overloaded",IF(K7<workload_config!$B$3,"Underutilized","Optimal")) -> Optimal | N7: =MAX(0,ROUND(F7*workload_config!$B$4/100-J7,0)) -> 8
A8: E022 | B8: Rekha Murthy | C8: Senior DevOps Engineer | D8: Cloud & DevOps | E8: 38 | F8: 40 | G8: =ROUND(E8/F8*100,0) -> 95 | H8: =SUMIFS(rebalance_recommendations!$J:$J,rebalance_recommendations!$K:$K,A8) -> 12 | I8: =SUMIFS(rebalance_recommendations!$J:$J,rebalance_recommendations!$M:$M,A8) -> 0 | J8: =E8-H8+I8 -> 26 | K8: =ROUND(J8/F8*100,0) -> 65 | L8: =IF(G8>=workload_config!$B$2,"Overloaded",IF(G8<workload_config!$B$3,"Underutilized","Optimal")) -> Overloaded | M8: =IF(K8>=workload_config!$B$2,"Overloaded",IF(K8<workload_config!$B$3,"Underutilized","Optimal")) -> Optimal | N8: =MAX(0,ROUND(F8*workload_config!$B$4/100-J8,0)) -> 6
A9: E019 | B9: Gautham Prabhu | C9: Senior DevOps Engineer | D9: Cloud & DevOps | E9: 36 | F9: 40 | G9: =ROUND(E9/F9*100,0) -> 90 | H9: =SUMIFS(rebalance_recommendations!$J:$J,rebalance_recommendations!$K:$K,A9) -> 9 | I9: =SUMIFS(rebalance_recommendations!$J:$J,rebalance_recommendations!$M:$M,A9) -> 0 | J9: =E9-H9+I9 -> 27 | K9: =ROUND(J9/F9*100,0) -> 68 | L9: =IF(G9>=workload_config!$B$2,"Overloaded",IF(G9<workload_config!$B$3,"Underutilized","Optimal")) -> Overloaded | M9: =IF(K9>=workload_config!$B$2,"Overloaded",IF(K9<workload_config!$B$3,"Underutilized","Optimal")) -> Optimal | N9: =MAX(0,ROUND(F9*workload_config!$B$4/100-J9,0)) -> 5
A10: E050 | B10: Amit Saxena | C10: Lead Project Manager | D10: Delivery & Quality | E10: 35 | F10: 40 | G10: =ROUND(E10/F10*100,0) -> 88 | H10: =SUMIFS(rebalance_recommendations!$J:$J,rebalance_recommendations!$K:$K,A10) -> 0 | I10: =SUMIFS(rebalance_recommendations!$J:$J,rebalance_recommendations!$M:$M,A10) -> 0 | J10: =E10-H10+I10 -> 35 | K10: =ROUND(J10/F10*100,0) -> 88 | L10: =IF(G10>=workload_config!$B$2,"Overloaded",IF(G10<workload_config!$B$3,"Underutilized","Optimal")) -> Overloaded | M10: =IF(K10>=workload_config!$B$2,"Overloaded",IF(K10<workload_config!$B$3,"Underutilized","Optimal")) -> Overloaded | N10: =MAX(0,ROUND(F10*workload_config!$B$4/100-J10,0)) -> 0
A11: E006 | B11: Pooja Bhat | C11: Backend Engineer | D11: Backend | E11: 34 | F11: 40 | G11: =ROUND(E11/F11*100,0) -> 85 | H11: =SUMIFS(rebalance_recommendations!$J:$J,rebalance_recommendations!$K:$K,A11) -> 0 | I11: =SUMIFS(rebalance_recommendations!$J:$J,rebalance_recommendations!$M:$M,A11) -> 0 | J11: =E11-H11+I11 -> 34 | K11: =ROUND(J11/F11*100,0) -> 85 | L11: =IF(G11>=workload_config!$B$2,"Overloaded",IF(G11<workload_config!$B$3,"Underutilized","Optimal")) -> Optimal | M11: =IF(K11>=workload_config!$B$2,"Overloaded",IF(K11<workload_config!$B$3,"Underutilized","Optimal")) -> Optimal | N11: =MAX(0,ROUND(F11*workload_config!$B$4/100-J11,0)) -> 0
A12: E057 | B12: Omkar Patil | C12: Junior QA Engineer | D12: Delivery & Quality | E12: 17 | F12: 20 | G12: =ROUND(E12/F12*100,0) -> 85 | H12: =SUMIFS(rebalance_recommendations!$J:$J,rebalance_recommendations!$K:$K,A12) -> 0 | I12: =SUMIFS(rebalance_recommendations!$J:$J,rebalance_recommendations!$M:$M,A12) -> 0 | J12: =E12-H12+I12 -> 17 | K12: =ROUND(J12/F12*100,0) -> 85 | L12: =IF(G12>=workload_config!$B$2,"Overloaded",IF(G12<workload_config!$B$3,"Underutilized","Optimal")) -> Optimal | M12: =IF(K12>=workload_config!$B$2,"Overloaded",IF(K12<workload_config!$B$3,"Underutilized","Optimal")) -> Optimal | N12: =MAX(0,ROUND(F12*workload_config!$B$4/100-J12,0)) -> 0
A13: E007 | B13: Harish Gowda | C13: Junior Backend Engineer | D13: Backend | E13: 33 | F13: 40 | G13: =ROUND(E13/F13*100,0) -> 83 | H13: =SUMIFS(rebalance_recommendations!$J:$J,rebalance_recommendations!$K:$K,A13) -> 0 | I13: =SUMIFS(rebalance_recommendations!$J:$J,rebalance_recommendations!$M:$M,A13) -> 0 | J13: =E13-H13+I13 -> 33 | K13: =ROUND(J13/F13*100,0) -> 83 | L13: =IF(G13>=workload_config!$B$2,"Overloaded",IF(G13<workload_config!$B$3,"Underutilized","Optimal")) -> Optimal | M13: =IF(K13>=workload_config!$B$2,"Overloaded",IF(K13<workload_config!$B$3,"Underutilized","Optimal")) -> Optimal | N13: =MAX(0,ROUND(F13*workload_config!$B$4/100-J13,0)) -> 0
... A61: E017 | B61: Nikhil Agarwal | C61: Senior DevOps Engineer | D61: Cloud & DevOps | E61: 12 | F61: 40 | G61: =ROUND(E61/F61*100,0) -> 30 | H61: =SUMIFS(rebalance_recommendations!$J:$J,rebalance_recommendations!$K:$K,A61) -> 0 | I61: =SUMIFS(rebalance_recommendations!$J:$J,rebalance_recommendations!$M:$M,A61) -> 14 | J61: =E61-H61+I61 -> 26 | K61: =ROUND(J61/F61*100,0) -> 65 | L61: =IF(G61>=workload_config!$B$2,"Overloaded",IF(G61<workload_config!$B$3,"Underutilized","Optimal")) -> Underutilized | M61: =IF(K61>=workload_config!$B$2,"Overloaded",IF(K61<workload_config!$B$3,"Underutilized","Optimal")) -> Optimal | N61: =MAX(0,ROUND(F61*workload_config!$B$4/100-J61,0)) -> 6

Sheet rebalance_log
A1: log_id | B1: moved_on | C1: task_id | D1: task_name | E1: from_employee_id | F1: from_name | G1: to_employee_id | H1: to_name | I1: hours_moved | J1: from_util_before_pct | K1: from_util_after_pct | L1: to_util_before_pct | M1: to_util_after_pct | N1: trigger | O1: manager_decision
A2: RL001 | B2: 2026-10-06 | C2: T095 | D2: A/B test analysis | E2: E026 | F2: Priya Nair | G2: E031 | H2: Rajesh Pandey | I2: 11 | J2: 126 | K2: 98 | L2: 38 | M2: 66 | N2: auto_rebalance | O2: accepted
A3: RL002 | B3: 2026-09-25 | C3: T053 | D3: Lambda workflows | E3: E024 | F3: Bhavana Rao | G3: E018 | H3: Fatima Khan | I3: 8 | J3: 115 | K3: 95 | L3: 53 | M3: 73 | N3: auto_rebalance | O3: accepted
A4: RL003 | B4: 2026-09-21 | C4: T140 | D4: Versioning clean-up | E4: E039 | F4: Kavya Reddy | G4: E049 | H4: Nandini Iyer | I4: 10 | J4: 110 | K4: 85 | L4: 37 | M4: 62 | N4: auto_rebalance | O4: accepted
A5: RL004 | B5: 2026-09-24 | C5: T059 | D5: Compose environments | E5: E022 | F5: Rekha Murthy | G5: E020 | H5: Swathi Hegde | I5: 9 | J5: 121 | K5: 99 | L5: 55 | M5: 77 | N5: auto_rebalance | O5: accepted
A6: RL005 | B6: 2026-09-29 | C6: T092 | D6: Data cleaning pipeline | E6: E032 | F6: Ishita Sen | G6: E030 | H6: Sneha Kamath | I6: 9 | J6: 105 | K6: 83 | L6: 56 | M6: 78 | N6: auto_rebalance | O6: accepted
A7: RL006 | B7: 2026-09-17 | C7: T142 | D7: Responsive layouts | E7: E048 | F7: Pranav Hegde | G7: E049 | H7: Nandini Iyer | I7: 8 | J7: 126 | K7: 106 | L7: 58 | M7: 78 | N7: auto_rebalance | O7: accepted
A8: RL007 | B8: 2026-10-01 | C8: T063 | D8: Image hardening | E8: E023 | F8: Yash Malhotra | G8: E021 | H8: Abhishek Tiwari | I8: 10 | J8: 109 | K8: 84 | L8: 55 | M8: 80 | N8: manager_manual | O8: modified
A9: RL008 | B9: 2026-09-27 | C9: T137 | D9: Admin console | E9: E042 | F9: Tarun Mishra | G9: E048 | H9: Pranav Hegde | I9: 11 | J9: 95 | K9: 67 | L9: 42 | M9: 70 | N9: auto_rebalance | O9: accepted
A10: RL009 | B10: 2026-09-24 | C10: T016 | D10: Versioning clean-up | E10: E008 | F10: Lakshmi Narayan | G10: E005 | H10: Sandeep Kulkarni | I10: 7 | J10: 96 | K10: 78 | L10: 41 | M10: 59 | N10: manager_manual | O10: accepted
A11: RL010 | B11: 2026-10-08 | C11: T048 | D11: Server patching | E11: E019 | F11: Gautham Prabhu | G11: E016 | H11: Suresh Babu | I11: 10 | J11: 117 | K11: 92 | L11: 55 | M11: 80 | N11: auto_rebalance | O11: accepted
A12: RL011 | B12: 2026-09-15 | C12: T039 | D12: Feature preparation | E12: E005 | F12: Sandeep Kulkarni | G12: E012 | H12: Manoj Kumar | I12: 7 | J12: 107 | K12: 89 | L12: 58 | M12: 76 | N12: manager_manual | O12: modified
A13: RL012 | B13: 2026-10-04 | C13: T082 | D13: Sales dashboards | E13: E031 | F13: Rajesh Pandey | G13: E028 | H13: Divya Menon | I13: 10 | J13: 117 | K13: 92 | L13: 46 | M13: 71 | N13: auto_rebalance | O13: accepted
... A17: RL016 | B17: 2026-09-14 | C17: T097 | D17: Ad-hoc analysis requests | E17: E037 | F17: Naveen Reddy | G17: E032 | H17: Ishita Sen | I17: 7 | J17: 126 | K17: 108 | L17: 59 | M17: 77 | N17: auto_rebalance | O17: accepted

Sheet workload_dashboard_summary
A1: Workload Rebalancing & Allocation - dashboard feed
A3: metric | B3: before_rebalance | C3: after_rebalance
A4: Overloaded (count) | B4: =COUNTIFS(workload_history!$A$2:$A$541,workload_config!$B$7,workload_history!$I$2:$I$541,"Overloaded") -> 9 | C4: =COUNTIF(rebalance_employee_impact!$M$2:$M$61,"Overloaded") -> 1
A5: Underutilized (count) | B5: =COUNTIFS(workload_history!$A$2:$A$541,workload_config!$B$7,workload_history!$I$2:$I$541,"Underutilized") -> 7 | C5: =COUNTIF(rebalance_employee_impact!$M$2:$M$61,"Underutilized") -> 1
A6: Optimal (count) | B6: =COUNTIFS(workload_history!$A$2:$A$541,workload_config!$B$7,workload_history!$I$2:$I$541,"Optimal") -> 44 | C6: =COUNTIF(rebalance_employee_impact!$M$2:$M$61,"Optimal") -> 58
A7: Overloaded (%) | B7: =B4/workload_config!$B$8 -> 0.15 | C7: =C4/workload_config!$B$8 -> 0.016666667
A8: Underutilized (%) | B8: =B5/workload_config!$B$8 -> 0.11666667 | C8: =C5/workload_config!$B$8 -> 0.016666667
A9: Optimal (%) | B9: =B6/workload_config!$B$8 -> 0.73333333 | C9: =C6/workload_config!$B$8 -> 0.96666667
A10: Tasks proposed to move | C10: =COUNTA(rebalance_recommendations!$A$2:$A$11) -> 10
A11: Hours moved per week | C11: =SUM(rebalance_recommendations!$J$2:$J$11) -> 104
A13: Notes: Before = week in workload_config!B7 from workload_history. After = rebalance_employee_impact. Percent cells are fractions formatted as %.

Sheet employee_skill_gaps
A1: gap_id | B1: employee_id | C1: employee_name | D1: department | E1: role | F1: skill_id | G1: skill_name | H1: skill_category | I1: current_level_direct | J1: effective_level | K1: required_level | L1: gap_levels | M1: gap_source | N1: driving_task_id | O1: driving_projects | P1: is_critical | Q1: interest_level | R1: status
A2: G001 | B2: E005 | C2: Sandeep Kulkarni | D2: Backend | E2: Backend Engineer | F2: S27 | G2: Linux | H2: DevOps | I2: 1 | J2: 1 | K2: 2 | L2: =K2-J2 -> 1 | M2: Current assignment | N2: T018 | O2: P05 | P2: 1 | R2: Open
A3: G002 | B3: E006 | C3: Pooja Bhat | D3: Backend | E3: Backend Engineer | F3: S16 | G3: PostgreSQL | H3: Database | I3: 1 | J3: 1 | K3: 2 | L3: =K3-J3 -> 1 | M3: Current assignment | N3: T019 | O3: P04 | P3: 0 | Q3: 3 | R3: Open
A4: G003 | B4: E007 | C4: Harish Gowda | D4: Backend | E4: Junior Backend Engineer | F4: S14 | G4: REST API Design | H4: Backend | I4: 1 | J4: 1 | K4: 2 | L4: =K4-J4 -> 1 | M4: Current assignment | N4: T022 | O4: P05 | P4: 0 | R4: Open
A5: G004 | B5: E007 | C5: Harish Gowda | D5: Backend | E5: Junior Backend Engineer | F5: S16 | G5: PostgreSQL | H5: Database | I5: 1 | J5: 1 | K5: 2 | L5: =K5-J5 -> 1 | M5: Current assignment | N5: T023 | O5: P02 | P5: 0 | R5: Open
A6: G005 | B6: E010 | C6: Deepak Chauhan | D6: Backend | E6: Junior Backend Engineer | F6: S26 | G6: CI/CD | H6: DevOps | I6: 1 | J6: 1 | K6: 2 | L6: =K6-J6 -> 1 | M6: Current assignment | N6: T033 | O6: P02 | P6: 0 | R6: Open
A7: G006 | B7: E013 | C7: Tanvi Deshpande | D7: Backend | E7: Junior Backend Engineer | F7: S13 | G7: Spring Boot | H7: Backend | I7: 1 | J7: 1 | K7: 2 | L7: =K7-J7 -> 1 | M7: Current assignment | N7: T041 | O7: P02 | P7: 0 | Q7: 3 | R7: Open
A8: G007 | B8: E013 | C8: Tanvi Deshpande | D8: Backend | E8: Junior Backend Engineer | F8: S15 | G8: SQL | H8: Database | I8: 1 | J8: 1 | K8: 2 | L8: =K8-J8 -> 1 | M8: Current assignment | N8: T042 | O8: P02 | P8: 0 | R8: Open
A9: G008 | B9: E013 | C9: Tanvi Deshpande | D9: Backend | E9: Junior Backend Engineer | F9: S23 | G9: Docker | H9: DevOps | I9: 1 | J9: 1 | K9: 2 | L9: =K9-J9 -> 1 | M9: Current assignment | N9: T040 | O9: P04 | P9: 0 | R9: Open
A10: G009 | B10: E015 | C10: Arjun Mehta | D10: Cloud & DevOps | E10: DevOps Engineer | F10: S24 | G10: Kubernetes | H10: DevOps | I10: 2 | J10: 2 | K10: 4 | L10: =K10-J10 -> 2 | M10: Upcoming project | O10: P08|P11 | P10: 1 | Q10: 5 | R10: Open
A11: G010 | B11: E016 | C11: Suresh Babu | D11: Cloud & DevOps | E11: Lead DevOps Engineer | F11: S24 | G11: Kubernetes | H11: DevOps | I11: 2 | J11: 2 | K11: 4 | L11: =K11-J11 -> 2 | M11: Upcoming project | O11: P08|P11 | P11: 1 | R11: Open
A12: G011 | B12: E016 | C12: Suresh Babu | D12: Cloud & DevOps | E12: Lead DevOps Engineer | F12: S40 | G12: MLOps | H12: AI/ML | I12: 0 | J12: 1 | K12: 3 | L12: =K12-J12 -> 2 | M12: Upcoming project | O12: P11 | P12: 1 | Q12: 4 | R12: In training
A13: G012 | B13: E017 | C13: Nikhil Agarwal | D13: Cloud & DevOps | E13: Senior DevOps Engineer | F13: S24 | G13: Kubernetes | H13: DevOps | I13: 2 | J13: 2 | K13: 4 | L13: =K13-J13 -> 2 | M13: Upcoming project | O13: P08|P11 | P13: 1 | Q13: 4 | R13: Open
A14: G013 | B14: E018 | C14: Fatima Khan | D14: Cloud & DevOps | E14: DevOps Engineer | F14: S01 | G14: Python | H14: Programming | I14: 1 | J14: 1 | K14: 2 | L14: =K14-J14 -> 1 | M14: Current assignment | N14: T052 | O14: P05 | P14: 0 | R14: Open
A15: G014 | B15: E018 | C15: Fatima Khan | D15: Cloud & DevOps | E15: DevOps Engineer | F15: S20 | G15: AWS | H15: Cloud | I15: 1 | J15: 1 | K15: 2 | L15: =K15-J15 -> 1 | M15: Current assignment | N15: T053 | O15: P05 | P15: 0 | R15: Open
A16: G015 | B16: E020 | C16: Swathi Hegde | D16: Cloud & DevOps | E16: Junior DevOps Engineer | F16: S23 | G16: Docker | H16: DevOps | I16: 1 | J16: 1 | K16: 2 | L16: =K16-J16 -> 1 | M16: Current assignment | N16: T059 | O16: P05 | P16: 0 | R16: Open
A17: G016 | B17: E026 | C17: Priya Nair | D17: Data & AI | E17: Senior Data Analyst | F17: S40 | G17: MLOps | H17: AI/ML | I17: 0 | J17: 1 | K17: 3 | L17: =K17-J17 -> 2 | M17: Upcoming project | O17: P11 | P17: 1 | Q17: 4 | R17: Open
A18: G017 | B18: E029 | C18: Aditya Bansal | D18: Data & AI | E18: Data Analyst | F18: S29 | G18: Pandas | H18: Data | I18: 1 | J18: 1 | K18: 2 | L18: =K18-J18 -> 1 | M18: Current assignment | N18: T087 | O18: P03 | P18: 0 | R18: Open
A19: G018 | B19: E029 | C19: Aditya Bansal | D19: Data & AI | E19: Data Analyst | F19: S39 | G19: NLP | H19: AI/ML | I19: 1 | J19: 1 | K19: 2 | L19: =K19-J19 -> 1 | M19: Current assignment | N19: T089 | O19: P06 | P19: 0 | R19: Open
A20: G019 | B20: E031 | C20: Rajesh Pandey | D20: Data & AI | E20: Lead Data Scientist | F20: S35 | G20: Apache Kafka | H20: Data | I20: 0 | J20: 1 | K20: 3 | L20: =K20-J20 -> 2 | M20: Upcoming project | O20: P09 | P20: 1 | R20: Open
A21: G020 | B21: E034 | C21: Pallavi Joshi | D21: Data & AI | E21: Junior Data Scientist | F21: S01 | G21: Python | H21: Programming | I21: 1 | J21: 1 | K21: 2 | L21: =K21-J21 -> 1 | M21: Current assignment | N21: T103 | O21: P05 | P21: 0 | R21: Open
A22: G021 | B22: E034 | C22: Pallavi Joshi | D22: Data & AI | E22: Junior Data Scientist | F22: S15 | G22: SQL | H22: Database | I22: 1 | J22: 1 | K22: 2 | L22: =K22-J22 -> 1 | M22: Current assignment | N22: T102 | O22: P06 | P22: 0 | R22: Open
A23: G022 | B23: E035 | C23: Arvind Swamy | D23: Data & AI | E23: Senior Data Analyst | F23: S35 | G23: Apache Kafka | H23: Data | I23: 0 | J23: 1 | K23: 3 | L23: =K23-J23 -> 2 | M23: Upcoming project | O23: P09 | P23: 1 | Q23: 5 | R23: In training
A24: G023 | B24: E040 | C24: Rohan Das | D24: Frontend & Mobile | E24: Frontend Developer | F24: S07 | G24: React | H24: Frontend | I24: 3 | J24: 3 | K24: 4 | L24: =K24-J24 -> 1 | M24: Upcoming project | O24: P09 | P24: 1 | R24: Open
A25: G024 | B25: E043 | C25: Anjali Nambiar | D25: Frontend & Mobile | E25: Junior Frontend Developer | F25: S09 | G25: HTML/CSS | H25: Frontend | I25: 1 | J25: 1 | K25: 2 | L25: =K25-J25 -> 1 | M25: Current assignment | N25: T124 | O25: P06 | P25: 0 | R25: Open
A26: G025 | B26: E046 | C26: Farhan Ali | D26: Frontend & Mobile | E26: Junior Frontend Developer | F26: S07 | G26: React | H26: Frontend | I26: 1 | J26: 1 | K26: 2 | L26: =K26-J26 -> 1 | M26: Current assignment | N26: T134 | O26: P06 | P26: 0 | R26: Open
A27: G026 | B27: E047 | C27: Ritu Sharma | D27: Frontend & Mobile | E27: Senior Frontend Developer | F27: S07 | G27: React | H27: Frontend | I27: 3 | J27: 3 | K27: 4 | L27: =K27-J27 -> 1 | M27: Upcoming project | O27: P09 | P27: 1 | R27: Open
A28: G027 | B28: E054 | C28: Bindu Madhavan | D28: Delivery & Quality | E28: QA Engineer | F28: S15 | G28: SQL | H28: Database | I28: 1 | J28: 1 | K28: 2 | L28: =K28-J28 -> 1 | M28: Current assignment | N28: T157 | O28: P02|P04 | P28: 1 | R28: Open
A29: G028 | B29: E055 | C29: Harsha Vardhan | D29: Delivery & Quality | E29: Senior Full-Stack Developer | F29: S07 | G29: React | H29: Frontend | I29: 3 | J29: 3 | K29: 4 | L29: =K29-J29 -> 1 | M29: Upcoming project | O29: P09 | P29: 1 | R29: Open
A30: G029 | B30: E056 | C30: Leena Fernandes | D30: Delivery & Quality | E30: Technical Writer | F30: S47 | G30: Agile/Scrum | H30: Management | I30: 1 | J30: 1 | K30: 2 | L30: =K30-J30 -> 1 | M30: Current assignment | N30: T162 | O30: P02 | P30: 0 | R30: Open
A31: G030 | B31: E058 | C31: Ayesha Siddiqui | D31: Delivery & Quality | E31: Senior UI/UX Designer | F31: S48 | G31: Technical Writing | H31: Soft | I31: 0 | J31: 1 | K31: 2 | L31: =K31-J31 -> 1 | M31: Upcoming project | O31: P10 | P31: 0 | Q31: 5 | R31: In training
A32: G031 | B32: E059 | C32: Sunil Rao | D32: Delivery & Quality | E32: Full-Stack Developer | F32: S07 | G32: React | H32: Frontend | I32: 1 | J32: 1 | K32: 2 | L32: =K32-J32 -> 1 | M32: Current assignment | N32: T169 | O32: P04 | P32: 0 | R32: Open
A33: G032 | B33: E060 | C33: Teja Reddy | D33: Delivery & Quality | E33: Junior Full-Stack Developer | F33: S01 | G33: Python | H33: Programming | I33: 1 | J33: 1 | K33: 2 | L33: =K33-J33 -> 1 | M33: Current assignment | N33: T171 | O33: P05 | P33: 0 | R33: Open
A34: G033 | B34: E060 | C34: Teja Reddy | D34: Delivery & Quality | E34: Junior Full-Stack Developer | F34: S10 | G34: Node.js | H34: Backend | I34: 1 | J34: 1 | K34: 2 | L34: =K34-J34 -> 1 | M34: Current assignment | N34: T170 | O34: P01 | P34: 1 | R34: Open

Sheet training_recommendations
A1: rec_id | B1: gap_id | C1: employee_id | D1: employee_name | E1: department | F1: skill_id | G1: skill_name | H1: current_level | I1: target_level | J1: gap_levels | K1: recommended_course_id | L1: recommended_course | M1: provider | N1: course_path | O1: path_duration_weeks | P1: course_hrs_per_week | Q1: path_cost_inr | R1: mentor_employee_id | S1: mentor_name | T1: priority_score | U1: priority_label | V1: reason | W1: alloc_hrs_after_rebalance | X1: capacity_hrs | Y1: util_with_training_pct | Z1: capacity_fit | AA1: planned_start | AB1: planned_end | AC1: status
A2: TR001 | B2: G001 | C2: E005 | D2: Sandeep Kulkarni | E2: Backend | F2: S27 | G2: Linux | H2: 1 | I2: 2 | J2: 1 | K2: C16 | L2: Linux System Administration | M2: Linux Foundation | N2: C16 | O2: 3 | P2: 4 | Q2: 14000 | T2: 80 | U2: =IF(T2>=70,"High",IF(T2>=40,"Medium","Low")) -> High | V2: Gap of 1 level(s) vs 2 required; reaches level 4 | W2: 27 | X2: 40 | Y2: =ROUND((W2+P2)/X2*100,0) -> 78 | Z2: =IF(Y2<=workload_config!$B$6,"Fits capacity","Exceeds capacity - defer") -> Fits capacity | AA2: 2026-10-19 | AB2: 2026-11-09 | AC2: recommended
A3: TR002 | B3: G002 | C3: E006 | D3: Pooja Bhat | E3: Backend | F3: S16 | G3: PostgreSQL | H3: 1 | I3: 2 | J3: 1 | L3: Mentorship / pair assignment (no catalog course) | M3: Internal | O3: 6 | P3: 2 | Q3: 0 | R3: E004 | S3: Vikram Joshi | T3: 50 | U3: =IF(T3>=70,"High",IF(T3>=40,"Medium","Low")) -> Medium | V3: No catalog course for PostgreSQL; mentor Vikram Joshi (level 3) | W3: 34 | X3: 40 | Y3: =ROUND((W3+P3)/X3*100,0) -> 90 | Z3: =IF(Y3<=workload_config!$B$6,"Fits capacity","Exceeds capacity - defer") -> Fits capacity | AA3: 2026-10-26 | AB3: 2026-12-07 | AC3: recommended
A4: TR003 | B4: G003 | C4: E007 | D4: Harish Gowda | E4: Backend | F4: S14 | G4: REST API Design | H4: 1 | I4: 2 | J4: 1 | L4: Mentorship / pair assignment (no catalog course) | M4: Internal | O4: 6 | P4: 2 | Q4: 0 | R4: E004 | S4: Vikram Joshi | T4: 43 | U4: =IF(T4>=70,"High",IF(T4>=40,"Medium","Low")) -> Medium | V4: No catalog course for REST API Design; mentor Vikram Joshi (level 5) | W4: 33 | X4: 40 | Y4: =ROUND((W4+P4)/X4*100,0) -> 88 | Z4: =IF(Y4<=workload_config!$B$6,"Fits capacity","Exceeds capacity - defer") -> Fits capacity | AA4: 2026-10-26 | AB4: 2026-12-07 | AC4: recommended
A5: TR004 | B5: G004 | C5: E007 | D5: Harish Gowda | E5: Backend | F5: S16 | G5: PostgreSQL | H5: 1 | I5: 2 | J5: 1 | L5: Mentorship / pair assignment (no catalog course) | M5: Internal | O5: 6 | P5: 2 | Q5: 0 | R5: E004 | S5: Vikram Joshi | T5: 43 | U5: =IF(T5>=70,"High",IF(T5>=40,"Medium","Low")) -> Medium | V5: No catalog course for PostgreSQL; mentor Vikram Joshi (level 3) | W5: 33 | X5: 40 | Y5: =ROUND((W5+P5)/X5*100,0) -> 88 | Z5: =IF(Y5<=workload_config!$B$6,"Fits capacity","Exceeds capacity - defer") -> Fits capacity | AA5: 2026-10-26 | AB5: 2026-12-07 | AC5: recommended
A6: TR005 | B6: G005 | C6: E010 | D6: Deepak Chauhan | E6: Backend | F6: S26 | G6: CI/CD | H6: 1 | I6: 2 | J6: 1 | K6: C15 | L6: CI/CD Pipelines with GitHub Actions | M6: Udemy | N6: C15 | O6: 3 | P6: 4 | Q6: 3500 | T6: 38 | U6: =IF(T6>=70,"High",IF(T6>=40,"Medium","Low")) -> Low | V6: Gap of 1 level(s) vs 2 required; reaches level 3 | W6: 33 | X6: 40 | Y6: =ROUND((W6+P6)/X6*100,0) -> 93 | Z6: =IF(Y6<=workload_config!$B$6,"Fits capacity","Exceeds capacity - defer") -> Fits capacity | AA6: 2026-11-02 | AB6: 2026-11-23 | AC6: recommended
A7: TR006 | B7: G006 | C7: E013 | D7: Tanvi Deshpande | E7: Backend | F7: S13 | G7: Spring Boot | H7: 1 | I7: 2 | J7: 1 | K7: C36 | L7: Spring Boot Microservices | M7: Udemy | N7: C36 | O7: 4 | P7: 5 | Q7: 4000 | T7: 50 | U7: =IF(T7>=70,"High",IF(T7>=40,"Medium","Low")) -> Medium | V7: Gap of 1 level(s) vs 2 required; reaches level 4; employee interest 3/5 | W7: 29 | X7: 40 | Y7: =ROUND((W7+P7)/X7*100,0) -> 85 | Z7: =IF(Y7<=workload_config!$B$6,"Fits capacity","Exceeds capacity - defer") -> Fits capacity | AA7: 2026-10-26 | AB7: 2026-11-23 | AC7: recommended
A8: TR007 | B8: G007 | C8: E013 | D8: Tanvi Deshpande | E8: Backend | F8: S15 | G8: SQL | H8: 1 | I8: 2 | J8: 1 | K8: C18 | L8: Advanced SQL and Query Tuning | M8: Udemy | N8: C18 | O8: 3 | P8: 4 | Q8: 3000 | T8: 43 | U8: =IF(T8>=70,"High",IF(T8>=40,"Medium","Low")) -> Medium | V8: Gap of 1 level(s) vs 2 required; reaches level 4 | W8: 29 | X8: 40 | Y8: =ROUND((W8+P8)/X8*100,0) -> 83 | Z8: =IF(Y8<=workload_config!$B$6,"Fits capacity","Exceeds capacity - defer") -> Fits capacity | AA8: 2026-10-26 | AB8: 2026-11-16 | AC8: recommended
A9: TR008 | B9: G008 | C9: E013 | D9: Tanvi Deshpande | E9: Backend | F9: S23 | G9: Docker | H9: 1 | I9: 2 | J9: 1 | K9: C14 | L9: Docker in Practice | M9: Udemy | N9: C14 | O9: 2 | P9: 4 | Q9: 3000 | T9: 43 | U9: =IF(T9>=70,"High",IF(T9>=40,"Medium","Low")) -> Medium | V9: Gap of 1 level(s) vs 2 required; reaches level 3 | W9: 29 | X9: 40 | Y9: =ROUND((W9+P9)/X9*100,0) -> 83 | Z9: =IF(Y9<=workload_config!$B$6,"Fits capacity","Exceeds capacity - defer") -> Fits capacity | AA9: 2026-10-26 | AB9: 2026-11-09 | AC9: recommended
A10: TR009 | B10: G009 | C10: E015 | D10: Arjun Mehta | E10: Cloud & DevOps | F10: S24 | G10: Kubernetes | H10: 2 | I10: 4 | J10: 2 | K10: C02 | L10: Kubernetes for Application Developers | M10: Linux Foundation | N10: C02 > C03 | O10: 10 | P10: 5 | Q10: 24000 | T10: 95 | U10: =IF(T10>=70,"High",IF(T10>=40,"Medium","Low")) -> High | V10: Gap of 2 level(s) vs 4 required; reaches level 4; employee interest 5/5 | W10: 24 | X10: 40 | Y10: =ROUND((W10+P10)/X10*100,0) -> 73 | Z10: =IF(Y10<=workload_config!$B$6,"Fits capacity","Exceeds capacity - defer") -> Fits capacity | AA10: 2026-10-19 | AB10: 2026-12-28 | AC10: recommended
A11: TR010 | B11: G010 | C11: E016 | D11: Suresh Babu | E11: Cloud & DevOps | F11: S24 | G11: Kubernetes | H11: 2 | I11: 4 | J11: 2 | K11: C02 | L11: Kubernetes for Application Developers | M11: Linux Foundation | N11: C02 > C03 | O11: 10 | P11: 5 | Q11: 24000 | T11: 75 | U11: =IF(T11>=70,"High",IF(T11>=40,"Medium","Low")) -> High | V11: Gap of 2 level(s) vs 4 required; reaches level 4 | W11: 32 | X11: 40 | Y11: =ROUND((W11+P11)/X11*100,0) -> 93 | Z11: =IF(Y11<=workload_config!$B$6,"Fits capacity","Exceeds capacity - defer") -> Fits capacity | AA11: 2026-10-19 | AB11: 2026-12-28 | AC11: recommended
A12: TR011 | B12: G011 | C12: E016 | D12: Suresh Babu | E12: Cloud & DevOps | F12: S40 | G12: MLOps | H12: 1 | I12: 3 | J12: 2 | K12: C06 | L12: MLOps Foundations | M12: Coursera | N12: C06 | O12: 5 | P12: 5 | Q12: 16000 | T12: 91 | U12: =IF(T12>=70,"High",IF(T12>=40,"Medium","Low")) -> High | V12: Gap of 2 level(s) vs 3 required; reaches level 3; employee interest 4/5 | W12: 32 | X12: 40 | Y12: =ROUND((W12+P12)/X12*100,0) -> 93 | Z12: =IF(Y12<=workload_config!$B$6,"Fits capacity","Exceeds capacity - defer") -> Fits capacity | AA12: 2026-10-19 | AB12: 2026-11-23 | AC12: already_enrolled
A13: TR012 | B13: G012 | C13: E017 | D13: Nikhil Agarwal | E13: Cloud & DevOps | F13: S24 | G13: Kubernetes | H13: 2 | I13: 4 | J13: 2 | K13: C02 | L13: Kubernetes for Application Developers | M13: Linux Foundation | N13: C02 > C03 | O13: 10 | P13: 5 | Q13: 24000 | T13: 91 | U13: =IF(T13>=70,"High",IF(T13>=40,"Medium","Low")) -> High | V13: Gap of 2 level(s) vs 4 required; reaches level 4; employee interest 4/5 | W13: 26 | X13: 40 | Y13: =ROUND((W13+P13)/X13*100,0) -> 78 | Z13: =IF(Y13<=workload_config!$B$6,"Fits capacity","Exceeds capacity - defer") -> Fits capacity | AA13: 2026-10-19 | AB13: 2026-12-28 | AC13: recommended
A14: TR013 | B14: G013 | C14: E018 | D14: Fatima Khan | E14: Cloud & DevOps | F14: S01 | G14: Python | H14: 1 | I14: 2 | J14: 1 | K14: C17 | L14: Python for Professionals | M14: Coursera | N14: C17 | O14: 5 | P14: 5 | Q14: 7000 | T14: 43 | U14: =IF(T14>=70,"High",IF(T14>=40,"Medium","Low")) -> Medium | V14: Gap of 1 level(s) vs 2 required; reaches level 4 | W14: 29 | X14: 40 | Y14: =ROUND((W14+P14)/X14*100,0) -> 85 | Z14: =IF(Y14<=workload_config!$B$6,"Fits capacity","Exceeds capacity - defer") -> Fits capacity | AA14: 2026-10-26 | AB14: 2026-11-30 | AC14: recommended
A15: TR014 | B15: G014 | C15: E018 | D15: Fatima Khan | E15: Cloud & DevOps | F15: S20 | G15: AWS | H15: 1 | I15: 2 | J15: 1 | K15: C10 | L15: AWS Solutions Architect Prep | M15: AWS Skill Builder | N15: C10 | O15: 5 | P15: 5 | Q15: 11000 | T15: 38 | U15: =IF(T15>=70,"High",IF(T15>=40,"Medium","Low")) -> Low | V15: Gap of 1 level(s) vs 2 required; reaches level 4 | W15: 29 | X15: 40 | Y15: =ROUND((W15+P15)/X15*100,0) -> 85 | Z15: =IF(Y15<=workload_config!$B$6,"Fits capacity","Exceeds capacity - defer") -> Fits capacity | AA15: 2026-11-02 | AB15: 2026-12-07 | AC15: recommended
A16: TR015 | B16: G015 | C16: E020 | D16: Swathi Hegde | E16: Cloud & DevOps | F16: S23 | G16: Docker | H16: 1 | I16: 2 | J16: 1 | K16: C14 | L16: Docker in Practice | M16: Udemy | N16: C14 | O16: 2 | P16: 4 | Q16: 3000 | T16: 43 | U16: =IF(T16>=70,"High",IF(T16>=40,"Medium","Low")) -> Medium | V16: Gap of 1 level(s) vs 2 required; reaches level 3 | W16: 31 | X16: 40 | Y16: =ROUND((W16+P16)/X16*100,0) -> 88 | Z16: =IF(Y16<=workload_config!$B$6,"Fits capacity","Exceeds capacity - defer") -> Fits capacity | AA16: 2026-10-26 | AB16: 2026-11-09 | AC16: recommended
A17: TR016 | B17: G016 | C17: E026 | D17: Priya Nair | E17: Data & AI | F17: S40 | G17: MLOps | H17: 1 | I17: 3 | J17: 2 | K17: C06 | L17: MLOps Foundations | M17: Coursera | N17: C06 | O17: 5 | P17: 5 | Q17: 16000 | T17: 91 | U17: =IF(T17>=70,"High",IF(T17>=40,"Medium","Low")) -> High | V17: Gap of 2 level(s) vs 3 required; reaches level 3; employee interest 4/5 | W17: 28 | X17: 40 | Y17: =ROUND((W17+P17)/X17*100,0) -> 83 | Z17: =IF(Y17<=workload_config!$B$6,"Fits capacity","Exceeds capacity - defer") -> Fits capacity | AA17: 2026-10-19 | AB17: 2026-11-23 | AC17: recommended
... A24: TR023 | B24: G023 | C24: E040 | D24: Rohan Das | E24: Frontend & Mobile | F24: S07 | G24: React | H24: 3 | I24: 4 | J24: 1 | K24: C31 | L24: Advanced React Patterns | M24: Udemy | N24: C31 | O24: 4 | P24: 5 | Q24: 4000 | T24: 58 | U24: =IF(T24>=70,"High",IF(T24>=40,"Medium","Low")) -> Medium | V24: Gap of 1 level(s) vs 4 required; reaches level 4 | W24: 25 | X24: 40 | Y24: =ROUND((W24+P24)/X24*100,0) -> 75 | Z24: =IF(Y24<=workload_config!$B$6,"Fits capacity","Exceeds capacity - defer") -> Fits capacity | AA24: 2026-10-26 | AB24: 2026-11-23 | AC24: recommended
A25: TR024 | B25: G024 | C25: E043 | D25: Anjali Nambiar | E25: Frontend & Mobile | F25: S09 | G25: HTML/CSS | H25: 1 | I25: 2 | J25: 1 | L25: Mentorship / pair assignment (no catalog course) | M25: Internal | O25: 6 | P25: 2 | Q25: 0 | R25: E039 | S25: Kavya Reddy | T25: 43 | U25: =IF(T25>=70,"High",IF(T25>=40,"Medium","Low")) -> Medium | V25: No catalog course for HTML/CSS; mentor Kavya Reddy (level 5) | W25: 24 | X25: 40 | Y25: =ROUND((W25+P25)/X25*100,0) -> 65 | Z25: =IF(Y25<=workload_config!$B$6,"Fits capacity","Exceeds capacity - defer") -> Fits capacity | AA25: 2026-10-26 | AB25: 2026-12-07 | AC25: recommended
A26: TR025 | B26: G025 | C26: E046 | D26: Farhan Ali | E26: Frontend & Mobile | F26: S07 | G26: React | H26: 1 | I26: 2 | J26: 1 | K26: C31 | L26: Advanced React Patterns | M26: Udemy | N26: C31 | O26: 4 | P26: 5 | Q26: 4000 | T26: 43 | U26: =IF(T26>=70,"High",IF(T26>=40,"Medium","Low")) -> Medium | V26: Gap of 1 level(s) vs 2 required; reaches level 4 | W26: 30 | X26: 40 | Y26: =ROUND((W26+P26)/X26*100,0) -> 88 | Z26: =IF(Y26<=workload_config!$B$6,"Fits capacity","Exceeds capacity - defer") -> Fits capacity | AA26: 2026-10-26 | AB26: 2026-11-23 | AC26: recommended
A27: TR026 | B27: G026 | C27: E047 | D27: Ritu Sharma | E27: Frontend & Mobile | F27: S07 | G27: React | H27: 3 | I27: 4 | J27: 1 | K27: C31 | L27: Advanced React Patterns | M27: Udemy | N27: C31 | O27: 4 | P27: 5 | Q27: 4000 | T27: 58 | U27: =IF(T27>=70,"High",IF(T27>=40,"Medium","Low")) -> Medium | V27: Gap of 1 level(s) vs 4 required; reaches level 4 | W27: 25 | X27: 40 | Y27: =ROUND((W27+P27)/X27*100,0) -> 75 | Z27: =IF(Y27<=workload_config!$B$6,"Fits capacity","Exceeds capacity - defer") -> Fits capacity | AA27: 2026-10-26 | AB27: 2026-11-23 | AC27: recommended
A28: TR027 | B28: G027 | C28: E054 | D28: Bindu Madhavan | E28: Delivery & Quality | F28: S15 | G28: SQL | H28: 1 | I28: 2 | J28: 1 | K28: C18 | L28: Advanced SQL and Query Tuning | M28: Udemy | N28: C18 | O28: 3 | P28: 4 | Q28: 3000 | T28: 80 | U28: =IF(T28>=70,"High",IF(T28>=40,"Medium","Low")) -> High | V28: Gap of 1 level(s) vs 2 required; reaches level 4 | W28: 27 | X28: 40 | Y28: =ROUND((W28+P28)/X28*100,0) -> 78 | Z28: =IF(Y28<=workload_config!$B$6,"Fits capacity","Exceeds capacity - defer") -> Fits capacity | AA28: 2026-10-19 | AB28: 2026-11-09 | AC28: recommended
A29: TR028 | B29: G028 | C29: E055 | D29: Harsha Vardhan | E29: Delivery & Quality | F29: S07 | G29: React | H29: 3 | I29: 4 | J29: 1 | K29: C31 | L29: Advanced React Patterns | M29: Udemy | N29: C31 | O29: 4 | P29: 5 | Q29: 4000 | T29: 58 | U29: =IF(T29>=70,"High",IF(T29>=40,"Medium","Low")) -> Medium | V29: Gap of 1 level(s) vs 4 required; reaches level 4 | W29: 30 | X29: 40 | Y29: =ROUND((W29+P29)/X29*100,0) -> 88 | Z29: =IF(Y29<=workload_config!$B$6,"Fits capacity","Exceeds capacity - defer") -> Fits capacity | AA29: 2026-10-26 | AB29: 2026-11-23 | AC29: recommended
A30: TR029 | B30: G029 | C30: E056 | D30: Leena Fernandes | E30: Delivery & Quality | F30: S47 | G30: Agile/Scrum | H30: 1 | I30: 2 | J30: 1 | L30: Mentorship / pair assignment (no catalog course) | M30: Internal | O30: 6 | P30: 2 | Q30: 0 | R30: E053 | S30: Kiran Kumar | T30: 43 | U30: =IF(T30>=70,"High",IF(T30>=40,"Medium","Low")) -> Medium | V30: No catalog course for Agile/Scrum; mentor Kiran Kumar (level 4) | W30: 21 | X30: 32 | Y30: =ROUND((W30+P30)/X30*100,0) -> 72 | Z30: =IF(Y30<=workload_config!$B$6,"Fits capacity","Exceeds capacity - defer") -> Fits capacity | AA30: 2026-10-26 | AB30: 2026-12-07 | AC30: recommended
A31: TR030 | B31: G030 | C31: E058 | D31: Ayesha Siddiqui | E31: Delivery & Quality | F31: S48 | G31: Technical Writing | H31: 1 | I31: 2 | J31: 1 | K31: C40 | L31: Technical Writing for Engineers | M31: Udemy | N31: C40 | O31: 2 | P31: 3 | Q31: 2500 | T31: 48 | U31: =IF(T31>=70,"High",IF(T31>=40,"Medium","Low")) -> Medium | V31: Gap of 1 level(s) vs 2 required; reaches level 3; employee interest 5/5 | W31: 25 | X31: 32 | Y31: =ROUND((W31+P31)/X31*100,0) -> 88 | Z31: =IF(Y31<=workload_config!$B$6,"Fits capacity","Exceeds capacity - defer") -> Fits capacity | AA31: 2026-10-26 | AB31: 2026-11-09 | AC31: already_enrolled
A32: TR031 | B32: G031 | C32: E059 | D32: Sunil Rao | E32: Delivery & Quality | F32: S07 | G32: React | H32: 1 | I32: 2 | J32: 1 | K32: C31 | L32: Advanced React Patterns | M32: Udemy | N32: C31 | O32: 4 | P32: 5 | Q32: 4000 | T32: 43 | U32: =IF(T32>=70,"High",IF(T32>=40,"Medium","Low")) -> Medium | V32: Gap of 1 level(s) vs 2 required; reaches level 4 | W32: 30 | X32: 40 | Y32: =ROUND((W32+P32)/X32*100,0) -> 88 | Z32: =IF(Y32<=workload_config!$B$6,"Fits capacity","Exceeds capacity - defer") -> Fits capacity | AA32: 2026-10-26 | AB32: 2026-11-23 | AC32: recommended
A33: TR032 | B33: G032 | C33: E060 | D33: Teja Reddy | E33: Delivery & Quality | F33: S01 | G33: Python | H33: 1 | I33: 2 | J33: 1 | K33: C17 | L33: Python for Professionals | M33: Coursera | N33: C17 | O33: 5 | P33: 5 | Q33: 7000 | T33: 38 | U33: =IF(T33>=70,"High",IF(T33>=40,"Medium","Low")) -> Low | V33: Gap of 1 level(s) vs 2 required; reaches level 4 | W33: 25 | X33: 40 | Y33: =ROUND((W33+P33)/X33*100,0) -> 75 | Z33: =IF(Y33<=workload_config!$B$6,"Fits capacity","Exceeds capacity - defer") -> Fits capacity | AA33: 2026-11-02 | AB33: 2026-12-07 | AC33: recommended
A34: TR033 | B34: G033 | C34: E060 | D34: Teja Reddy | E34: Delivery & Quality | F34: S10 | G34: Node.js | H34: 1 | I34: 2 | J34: 1 | K34: C33 | L34: Node.js Services at Scale | M34: Pluralsight | N34: C33 | O34: 4 | P34: 5 | Q34: 10000 | T34: 80 | U34: =IF(T34>=70,"High",IF(T34>=40,"Medium","Low")) -> High | V34: Gap of 1 level(s) vs 2 required; reaches level 4 | W34: 25 | X34: 40 | Y34: =ROUND((W34+P34)/X34*100,0) -> 75 | Z34: =IF(Y34<=workload_config!$B$6,"Fits capacity","Exceeds capacity - defer") -> Fits capacity | AA34: 2026-10-19 | AB34: 2026-11-16 | AC34: recommended

Sheet course_enrollments
A1: enrollment_id | B1: employee_id | C1: employee_name | D1: department | E1: course_id | F1: course_title | G1: skill_id | H1: enrolled_on | I1: start_date | J1: end_date | K1: status | L1: progress_pct | M1: score | N1: cost_inr | O1: level_before | P1: level_after | Q1: source
A2: EN001 | B2: E016 | C2: Suresh Babu | D2: Cloud & DevOps | E2: C06 | F2: MLOps Foundations | G2: S40 | H2: 2026-09-23 | I2: 2026-09-28 | J2: 2026-11-02 | K2: in_progress | L2: 50 | N2: 16000 | O2: 0 | Q2: manager_assigned
A3: EN002 | B3: E035 | C3: Arvind Swamy | D3: Data & AI | E3: C04 | F3: Kafka Essentials | G3: S35 | H3: 2026-09-30 | I3: 2026-10-05 | J3: 2026-10-26 | K3: in_progress | L3: 35 | N3: 9000 | O3: 0 | Q3: manager_assigned
A4: EN003 | B4: E058 | C4: Ayesha Siddiqui | D4: Delivery & Quality | E4: C40 | F4: Technical Writing for Engineers | G4: S48 | H4: 2026-09-30 | I4: 2026-10-05 | J4: 2026-10-19 | K4: in_progress | L4: 20 | N4: 2500 | O4: 0 | Q4: manager_assigned
A5: EN004 | B5: E030 | C5: Sneha Kamath | D5: Data & AI | E5: C18 | F5: Advanced SQL and Query Tuning | G5: S15 | H5: 2026-07-20 | I5: 2026-07-26 | J5: 2026-08-16 | K5: completed | L5: 100 | M5: 90 | N5: 3000 | O5: 2 | P5: 4 | Q5: self_enrolled
A6: EN005 | B6: E003 | C6: Karthik Subramanian | D6: Backend | E6: C16 | F6: Linux System Administration | G6: S27 | H6: 2026-04-27 | I6: 2026-05-03 | J6: 2026-05-24 | K6: completed | L6: 100 | M6: 97 | N6: 14000 | O6: 2 | P6: 4 | Q6: self_enrolled
A7: EN006 | B7: E004 | C7: Vikram Joshi | D7: Backend | E7: C35 | F7: Go for Backend Engineers | G7: S05 | H7: 2026-06-08 | I7: 2026-06-14 | J7: 2026-07-12 | K7: completed | L7: 100 | M7: 78 | N7: 9000 | O7: 1 | P7: 3 | Q7: manager_assigned
A8: EN007 | B8: E026 | C8: Priya Nair | D8: Data & AI | E8: C18 | F8: Advanced SQL and Query Tuning | G8: S15 | H8: 2026-03-20 | I8: 2026-03-26 | J8: 2026-04-16 | K8: completed | L8: 100 | M8: 93 | N8: 3000 | O8: 2 | P8: 4 | Q8: self_enrolled
A9: EN008 | B9: E036 | C9: Zoya Ansari | D9: Data & AI | E9: C18 | F9: Advanced SQL and Query Tuning | G9: S15 | H9: 2026-05-25 | I9: 2026-05-31 | J9: 2026-06-21 | K9: completed | L9: 100 | M9: 85 | N9: 3000 | O9: 2 | P9: 4 | Q9: self_enrolled
A10: EN009 | B10: E040 | C10: Rohan Das | D10: Frontend & Mobile | E10: C32 | F10: TypeScript Deep Dive | G10: S04 | H10: 2026-06-23 | I10: 2026-06-29 | J10: 2026-07-13 | K10: completed | L10: 100 | M10: 95 | N10: 3000 | O10: 1 | P10: 3 | Q10: manager_assigned
A11: EN010 | B11: E028 | C11: Divya Menon | D11: Data & AI | E11: C23 | F11: Data Engineering Professional Path | G11: S32 | H11: 2026-03-21 | I11: 2026-03-27 | J11: 2026-05-08 | K11: completed | L11: 100 | M11: 73 | N11: 20000 | O11: 2 | P11: 4 | Q11: self_enrolled
A12: EN011 | B12: E023 | C12: Yash Malhotra | D12: Cloud & DevOps | E12: C08 | F12: Terraform Basics | G12: S25 | H12: 2026-05-21 | I12: 2026-05-27 | J12: 2026-06-10 | K12: completed | L12: 100 | M12: 97 | N12: 3500 | O12: 0 | P12: 2 | Q12: manager_assigned
A13: EN012 | B13: E031 | C13: Rajesh Pandey | D13: Data & AI | E13: C18 | F13: Advanced SQL and Query Tuning | G13: S15 | H13: 2026-04-28 | I13: 2026-05-04 | J13: 2026-05-25 | K13: completed | L13: 100 | M13: 78 | N13: 3000 | O13: 2 | P13: 4 | Q13: manager_assigned
A14: EN013 | B14: E026 | C14: Priya Nair | D14: Data & AI | E14: C19 | F14: Applied Data Analytics | G14: S28 | H14: 2026-07-11 | I14: 2026-07-17 | J14: 2026-08-14 | K14: completed | L14: 100 | M14: 86 | N14: 9000 | O14: 2 | P14: 4 | Q14: manager_assigned
A15: EN014 | B15: E001 | C15: Ravi Shankar | D15: Backend | E15: C19 | F15: Applied Data Analytics | G15: S28 | H15: 2026-06-12 | I15: 2026-06-18 | J15: 2026-07-16 | K15: completed | L15: 100 | M15: 77 | N15: 9000 | O15: 2 | P15: 4 | Q15: self_enrolled
A16: EN015 | B16: E024 | C16: Bhavana Rao | D16: Cloud & DevOps | E16: C30 | F16: Secure Coding and Threat Modelling | G16: S41 | H16: 2026-06-22 | I16: 2026-06-28 | J16: 2026-07-26 | K16: completed | L16: 100 | M16: 79 | N16: 0 | O16: 1 | P16: 3 | Q16: manager_assigned
... A27: EN026 | B27: E026 | C27: Priya Nair | D27: Data & AI | E27: C26 | F27: Statistics for Data Science | G27: S36 | H27: 2026-06-28 | I27: 2026-07-04 | J27: 2026-08-08 | K27: completed | L27: 100 | M27: 76 | N27: 8000 | O27: 2 | P27: 4 | Q27: manager_assigned

Sheet training_budget
A1: department | B1: annual_budget_inr | C1: spent_completed_inr | D1: committed_in_progress_inr | E1: pending_recommendations_inr | F1: remaining_inr | G1: budget_used_pct
A2: Backend | B2: 400000 | C2: =SUMIFS(course_enrollments!$N$2:$N$27,course_enrollments!$D$2:$D$27,A2,course_enrollments!$K$2:$K$27,"completed") -> 44000 | D2: =SUMIFS(course_enrollments!$N$2:$N$27,course_enrollments!$D$2:$D$27,A2,course_enrollments!$K$2:$K$27,"in_progress") -> 0 | E2: =SUMIFS(training_recommendations!$Q$2:$Q$34,training_recommendations!$E$2:$E$34,A2,training_recommendations!$AC$2:$AC$34,"recommended") -> 27500 | F2: =B2-C2-D2-E2 -> 328500 | G2: =IF(B2=0,0,(C2+D2+E2)/B2) -> 0.17875
A3: Cloud & DevOps | B3: 500000 | C3: =SUMIFS(course_enrollments!$N$2:$N$27,course_enrollments!$D$2:$D$27,A3,course_enrollments!$K$2:$K$27,"completed") -> 36000 | D3: =SUMIFS(course_enrollments!$N$2:$N$27,course_enrollments!$D$2:$D$27,A3,course_enrollments!$K$2:$K$27,"in_progress") -> 16000 | E3: =SUMIFS(training_recommendations!$Q$2:$Q$34,training_recommendations!$E$2:$E$34,A3,training_recommendations!$AC$2:$AC$34,"recommended") -> 93000 | F3: =B3-C3-D3-E3 -> 355000 | G3: =IF(B3=0,0,(C3+D3+E3)/B3) -> 0.29
A4: Data & AI | B4: 600000 | C4: =SUMIFS(course_enrollments!$N$2:$N$27,course_enrollments!$D$2:$D$27,A4,course_enrollments!$K$2:$K$27,"completed") -> 61500 | D4: =SUMIFS(course_enrollments!$N$2:$N$27,course_enrollments!$D$2:$D$27,A4,course_enrollments!$K$2:$K$27,"in_progress") -> 9000 | E4: =SUMIFS(training_recommendations!$Q$2:$Q$34,training_recommendations!$E$2:$E$34,A4,training_recommendations!$AC$2:$AC$34,"recommended") -> 64000 | F4: =B4-C4-D4-E4 -> 465500 | G4: =IF(B4=0,0,(C4+D4+E4)/B4) -> 0.22416667
A5: Delivery & Quality | B5: 250000 | C5: =SUMIFS(course_enrollments!$N$2:$N$27,course_enrollments!$D$2:$D$27,A5,course_enrollments!$K$2:$K$27,"completed") -> 3000 | D5: =SUMIFS(course_enrollments!$N$2:$N$27,course_enrollments!$D$2:$D$27,A5,course_enrollments!$K$2:$K$27,"in_progress") -> 2500 | E5: =SUMIFS(training_recommendations!$Q$2:$Q$34,training_recommendations!$E$2:$E$34,A5,training_recommendations!$AC$2:$AC$34,"recommended") -> 28000 | F5: =B5-C5-D5-E5 -> 216500 | G5: =IF(B5=0,0,(C5+D5+E5)/B5) -> 0.134
A6: Frontend & Mobile | B6: 350000 | C6: =SUMIFS(course_enrollments!$N$2:$N$27,course_enrollments!$D$2:$D$27,A6,course_enrollments!$K$2:$K$27,"completed") -> 3000 | D6: =SUMIFS(course_enrollments!$N$2:$N$27,course_enrollments!$D$2:$D$27,A6,course_enrollments!$K$2:$K$27,"in_progress") -> 0 | E6: =SUMIFS(training_recommendations!$Q$2:$Q$34,training_recommendations!$E$2:$E$34,A6,training_recommendations!$AC$2:$AC$34,"recommended") -> 12000 | F6: =B6-C6-D6-E6 -> 335000 | G6: =IF(B6=0,0,(C6+D6+E6)/B6) -> 0.042857143

Sheet skill_supply_vs_demand
A1: skill_id | B1: skill_name | C1: category | D1: required_by_projects | E1: max_min_level_required | F1: has_critical_requirement | G1: qualified_employees | H1: qualified_available | I1: near_qualified_1_2_below | J1: employees_interested_4plus | K1: bench_status
A2: S01 | B2: Python | C2: Programming | D2: P03|P05|P06|P08|P10|P11 | E2: 4 | F2: 1 | G2: 11 | H2: 7 | I2: 24 | J2: 0 | K2: =IF(H2=0,"Critical gap",IF(H2<3,"Thin bench","OK")) -> OK
A3: S02 | B3: Java | C3: Programming | D3: P04 | E3: 3 | F3: 0 | G3: 1 | H3: 1 | I3: 3 | J3: 1 | K3: =IF(H3=0,"Critical gap",IF(H3<3,"Thin bench","OK")) -> Thin bench
A4: S07 | B4: React | C4: Frontend | D4: P01|P04|P06|P09 | E4: 4 | F4: 1 | G4: 1 | H4: 1 | I4: 9 | J4: 0 | K4: =IF(H4=0,"Critical gap",IF(H4<3,"Thin bench","OK")) -> Thin bench
A5: S10 | B5: Node.js | C5: Backend | D5: P09 | E5: 3 | F5: 0 | G5: 8 | H5: 6 | I5: 18 | J5: 2 | K5: =IF(H5=0,"Critical gap",IF(H5<3,"Thin bench","OK")) -> OK
A6: S12 | B6: FastAPI | C6: Backend | D6: P06 | E6: 3 | F6: 0 | G6: 11 | H6: 7 | I6: 29 | J6: 4 | K6: =IF(H6=0,"Critical gap",IF(H6<3,"Thin bench","OK")) -> OK
A7: S13 | B7: Spring Boot | C7: Backend | D7: P04 | E7: 3 | F7: 0 | G7: 1 | H7: 0 | I7: 19 | J7: 1 | K7: =IF(H7=0,"Critical gap",IF(H7<3,"Thin bench","OK")) -> Critical gap
A8: S14 | B8: REST API Design | C8: Backend | D8: P01 | E8: 3 | F8: 0 | G8: 13 | H8: 9 | I8: 9 | J8: 2 | K8: =IF(H8=0,"Critical gap",IF(H8<3,"Thin bench","OK")) -> OK
A9: S15 | B9: SQL | C9: Database | D9: P05|P07|P10 | E9: 4 | F9: 1 | G9: 14 | H9: 10 | I9: 14 | J9: 0 | K9: =IF(H9=0,"Critical gap",IF(H9<3,"Thin bench","OK")) -> OK
A10: S16 | B10: PostgreSQL | C10: Database | D10: P04 | E10: 3 | F10: 0 | G10: 17 | H10: 12 | I10: 13 | J10: 1 | K10: =IF(H10=0,"Critical gap",IF(H10<3,"Thin bench","OK")) -> OK
A11: S19 | B11: Cloud Computing | C11: Cloud | D11: P08|P09|P11 | E11: 3 | F11: 1 | G11: 8 | H11: 6 | I11: 12 | J11: 2 | K11: =IF(H11=0,"Critical gap",IF(H11<3,"Thin bench","OK")) -> OK
A12: S20 | B12: AWS | C12: Cloud | D12: P02 | E12: 4 | F12: 1 | G12: 6 | H12: 4 | I12: 8 | J12: 1 | K12: =IF(H12=0,"Critical gap",IF(H12<3,"Thin bench","OK")) -> OK
A13: S22 | B13: GCP | C13: Cloud | D13: P07 | E13: 3 | F13: 0 | G13: 6 | H13: 4 | I13: 15 | J13: 2 | K13: =IF(H13=0,"Critical gap",IF(H13<3,"Thin bench","OK")) -> OK
... A34: S48 | B34: Technical Writing | C34: Soft | D34: P10 | E34: 2 | F34: 0 | G34: 3 | H34: 2 | I34: 57 | J34: 2 | K34: =IF(H34=0,"Critical gap",IF(H34<3,"Thin bench","OK")) -> Thin bench

Sheet skill_gap_dashboard_summary
A1: skill | B1: gap | C1: recommended | D1: action | E1: open_gaps | F1: in_training | G1: critical_gaps | H1: avg_gap_levels | I1: top_priority_label
